Workbook
Name ListAssignmentType: 'Dropdown Lists'!$N$2:$N$3
Name ListAuthorizedUse: 'Dropdown Lists'!$F$2:$F$9
Name ListDataControlType: 'Dropdown Lists'!$V$2:$V$11
Name ListInterestAppraised: 'Dropdown Lists'!$E$2:$E$5
Name ListOutputType: 'Dropdown Lists'!$T$2:$T$10
Name ListPropertySubtype: 'Dropdown Lists'!$C$2:$C$4
Name ListPropertyType: 'Dropdown Lists'!$B$2:$B$10
Name ListStateofImprovements: 'Dropdown Lists'!$H$2:$H$3
Name ListValuationScenario: 'Dropdown Lists'!$J$2:$J$4
Name ListYesNo: 'Dropdown Lists'!$W$2:$W$3

Sheet Field Registry
C1: VALTA Field Name | D1: VALTA Field Label/UI | E1: Data Control Type | F1: Source Type | G1: Dropdown List | H1: New Field | I1: Required | J1: App Location | K1: Valcre Field Name | L1: Valcre Field Label/UI | M1: Valcre Field ID | N1: Valcre Record Location | O1: Valcre Field Key (API) | P1: Used In Outputs | Q1: Description | R1: Owner | S1: Status
C2: JobNumber | D2: Job Number | E2: Alpha Numeric | F2: Valcre API | H2: No | I2: Yes | K2: Number | L2: Job Number | N2: Job
C3: JobName | D3: Job Name | E3: Alpha Numeric | F3: User Input | H3: No | I3: Yes | K3: Name | L3: Job Name | N3: Job
C4: JobStatus | D4: Job Status | E4: Select one option | F4: User Input | H4: No | I4: Yes | K4: Status | L4: Status | N4: Job
C5: SubjectProperty | D5: Subject Property | E5: Alpha Numeric | F5: Valcre API | H5: No | I5: Yes | K5: Subject Property | L5: Property._DisplayName | N5: Job
C6: ClientCompanyName | D6: Client Company Name | E6: Alpha Numeric | F6: User Input | H6: No | I6: Yes | K6: Client | L6: Client._DisplayName | N6: Job
C7: ClientOrganizationAddress | D7: Client Organization Address | E7: Alpha Numeric | F7: User Input | H7: No | I7: Yes | K7: Various | L7: Various | N7: Contact
C8: ClientFirstName | D8: Client First Name | E8: Text | F8: User Input | H8: No | I8: Yes | K8: First Name | L8: FirstName | N8: Contact
C9: ClientLastName | D9: Client Last Name | E9: Text | F9: User Input | H9: No | I9: Yes | K9: Last Name | L9: LastName | N9: Contact
C10: ClientTitle | D10: Client Title | E10: Text | F10: User Input | H10: No | I10: Yes | K10: Title | L10: Title | N10: Contact
C11: ClientPhone | D11: Client Phone | E11: Text | F11: User Input | H11: No | I11: Yes | K11: Phone | L11: PhoneNumber | N11: Contact
C12: ClientEmail | D12: Client Email | E12: Text | F12: User Input | H12: No | I12: Yes | K12: Email | L12: Email | N12: Contact
C13: PropertyName | D13: Property Name | E13: Alpha Numeric | F13: User Input | H13: No | I13: Yes | K13: Name | L13: Name | N13: Property
C14: PropertyAddress | D14: Property Address | E14: Alpha Numeric | F14: User Input | H14: No | I14: Yes | K14: Street Address | L14: AddressStreet | N14: Property
C15: PropertyType | D15: Property Type | E15: Select one option | F15: User Input | G15: ListPropertyType | H15: No | I15: Yes | K15: Property Type | L15: Types | N15: Property
C16: PropertySubtype | D16: Property Subtype | E16: Select one option | F16: User Input | G16: ListPropertySubtype | H16: Yes | I16: Yes | K16: Subtype | L16: SecondaryType | N16: Property
C17: Tenancy | D17: Tenancy | E17: Select one option | F17: User Input | G17: ListTenancy | H17: Yes | I17: Yes | N17: Job
C18: StateofImprovements | D18: State of Improvements | E18: Select one option | F18: Logic | G18: ListSateofImprovements | H18: Yes | I18: Yes | N18: Job
C19: StatusofImprovements | D19: Status of Improvements | E19: Select one option | F19: User Input | G19: ListSatusofImprovements | H19: Yes | I19: Yes | N19: Job
C20: InterestAppraised | D20: Interest Appraised | E20: Select multiple options | F20: User Input | G20: ListInterestAppraised | H20: Yes | I20: Yes | N20: Job
C21: AuthorizedUse | D21: Authorized Use | E21: Select one option | F21: User Input | G21: ListAuthorizedUse | H21: Yes | I21: Yes | N21: Job
C22: ValueScenarios | D22: Value Scenario (s) | E22: Select multiple options | F22: User Input | G22: ListValueScenarios | H22: Yes | I22: Yes | N22: Job
C23: ApproachestoValue | D23: Approaches to Value | E23: Select multiple options | F23: Logic | G23: ListApproachestoValue | H23: Yes | I23: Yes | N23: Job
C24: AssignmentType | D24: Assignment Type | E24: Select one option | F24: User Input | G24: ListAssignmentType | H24: No | I24: Yes | N24: Job
C25: ReportType | D25: Report Type | E25: Select one option | F25: User Input | G25: ListReportType | H25: Yes | I25: Yes | N25: Job
C26: DesktopReport | D26: Desktop Report | E26: Select one option | F26: User Input | G26: ListYes/No | H26: Yes | I26: Yes | N26: Job
C27: Valuetimeframe | D27: Value Timeframe | E27: Select one option | F27: User Input | G27: ListValueTimeFrame | H27: Yes | I27: Yes | N27: Job
C28: InspectionDate | D28: Inspection Date | E28: Date | F28: User Input | H28: No | I28: Yes | K28: InspectionDate | L28: Inspection Date | N28: Job
C29: Fee | D29: Fee | E29: Whole Number | F29: Calculated | H29: No | I29: Yes | K29: Fee | L29: Fee | N29: Job
C30: DeliveryTime | D30: Delivery Time | E30: Whole Number | F30: User Input | H30: Yes | I30: No
C31: PaidDate | D31: Paid Date | E31: Date | F31: Logic | H31: No | I31: No | K31: PaidDate | L31: Paid Date | N31: Job
C32: Paid | D32: Paid | E32: Checkbox | F32: Logic | H32: No | I32: No
C33: RequestDate | D33: Request Date | E33: Date | F33: Logic | H33: No | I33: No | K33: BidDate | L33: Bid Date | N33: Job
C34: SignedDate | D34: Signed Date | E34: Date | F34: Logic | H34: No | I34: No | K34: AwardDate | L34: Awarded Date | N34: Job
C35: DueDate | D35: Due Date | E35: Date | F35: Logic | H35: No | I35: No | K35: DueDate | L35: Due Date | N35: Job
C36: AmountPaid | D36: Amount Paid | E36: Decimal | F36: Logic | H36: No | I36: No | K36: AmountPaid | L36: Amount Paid | N36: Job
C37: ClientDocuments | D37: Client Documents | E37: Select multiple options | F37: Logic | G37: ListClientDocuments | H37: Yes | I37: Yes
C38: TransactionStatus | D38: Transaction Status | E38: Select multiple options | F38: User Input | G38: ListTransactionStatus | H38: Yes | I38: Yes | N38: Job
C39: ZoningStatus | D39: Zoning Status | E39: Select one option | F39: User Input | G39: ListZoningStatus | H39: Yes | I39: Yes | N39: Job
C40: LandMetric | D40: Land $/Metric | E40: Select one option | F40: User Input | G40: ListLand$/Metric | H40: Yes | I40: Yes | N40: Job
...

Sheet Dropdown Lists
A1: DropdownLists | B1: ListPropertyType | C1: ListPropertySubtype | D1: ListTenancy | E1: ListInterestAppraised | F1: ListAuthorizedUse | G1: ListValueTimeFrame | H1: ListSateofImprovements | I1: ListSatusofImprovements | J1: ListValueScenarios | K1: ListApproachestoValue | L1: ListMethod | M1: ListReportType | N1: ListAssignmentType | O1: ListTransactionStatus | P1: ListClientDocuments | Q1: ListZoningStatus | R1: ListLand$/Metric | S1: ListSourceType | T1: ListOutputType | U1: ListValcreRecordLocation | V1: ListDataControlType | W1: ListYes/No | X1: ListOutputLocation | Y1: Used In Excel | Z1: Used In Word
A2: ListPropertyType | B2: Multifamily | C2: Apartment | D2: Multi-Tenant | E2: Fee Simple | F2: First Mortgage Financing | G2: Current | H2: Existing | I2: Existing - Completed | J2: As Is Vacant Land | K2: Land Direct Comparison Approach | L2: Direct Capitalization Method | M2: Comprehensive | N2: Single Property | O2: Not Applicable | P2: Previous Appraisal | S2: User Input | T2: LOE | U2: Job | V2: Text | W2: Yes | Y2: HOME | Z2: LOT
A3: ListPropertySubtype | B3: Self-Storage | C3: Townhouse | D3: Owner Occupied | E3: Leased Fee Interest | F3: Financial Reporting | G3: Prospective | H3: Proposed | I3: Existing - Renovated | J3: As If Vacant Land | K3: Cost Approach | L3: Discounted Cash Flow Method | M3: Concise | N3: Multiple Properties | O3: Listed | P3: Property Details | S3: Valcre API | T3: Excel | U3: Contact | V3: Multiple lines of text | W3: No | Y3: EXEC | Z3: Exec Summ
A4: ListTenancy | B4: Retail | C4: Mixed Use | D4: Partial Owner Occupied | E4: Leasehold Estate | F4: Insurance | G4: Retrospective | H4: Vacant Land | I4: Existing - Under Renovation | J4: As If Complete & Stabilized | K4: Direct Comparison Approach | M4: Form | O4: Under Contract | P4: Proforma | S4: Calculated | T4: Word | U4: Property | V4: Whole Number | Y4: MAP
A5: ListInterestAppraised | B5: Industrial | D5: Single-Tenant | E5: Going Concern | F5: Internal Decision-Making | I5: Existing - To Be Renovated | J5: As-Is | K5: Income Approach | P5: Unit Mix | S5: Logic | T5: LOR | U5: Building | V5: Decimal | Y5: IMPRV
A6: ListAuthorizedUse | B6: Office | D6: Unkown | F6: Acquisition-Disposition | I6: Proposed - Vacant Land | J6: As Stabilized | P6: Rent Roll | T6: ClickUP | U6: Parcel | V6: Select one option
A7: ListValueTimeFrame | B7: Land | D7: Vacant | F7: Estate Planning | I7: Proposed - Improved Land (Demolition Required) | J7: As If Complete & Stabilized - Renovated | P7: Historical Operating Expenses | T7: QBO | V7: Select multiple options
A8: ListSateofImprovements | B8: Hotel | F8: Litigation | I8: Proposed - Under Construction | J8: As If Complete - Rezoned | P8: Development Permit Drawings | T8: LOE, Excel, Word | V8: Checkbox
A9: ListSatusofImprovements | B9: Seniors | F9: GST | J9: As If Complete - Serviced | P9: Contact for Property Tour | T9: LOR, Excel, Word, CU | V9: Date
A10: ListApproachestoValue | B10: Other | J10: As If Complete - Subdivided | P10: Purchase & Sale Agreement | T10: LOE, Excel, Word, LOR, CU | V10: Calculation
A11: ListMethod | J11: Insurable Replacement Cost | P11: Environmental Reports | T11: LOE, Excel, Word, LOR, CU, QBO | V11: Alpha Numeric
A12: ListValueScenarios | P12: Property Condition Reports
A13: ListReportType
A14: ListAssignmentType
A15: ListTransactionStatus
A16: ListClientDocuments
A17: ListZoningStatus
A18: ListLand$/Metric
A19: ListSourceType
A20: ListOutputType
A21: ListValcreRecordLocation
A22: ListDataControlType
A23: ListYes/No
A24: ListOutputLocation

Sheet Rules Matrix
A1: Rule ID | B1: Rule Set ID | C1: Rule Group | D1: Rule Role | E1: Logic Type | F1: Rule Type | G1: Valta Field Name | H1: Operator | I1: Dropdown Value | K1: Valta Field Name | L1: Result Value | M1: Text ID | N1: Priority
A2: R001 | B2: 100-Interest | C2: Interest Rule | D2: =+Types!F4 -> Condition + Output | E2: =+Types!H2 -> And | F2: Set Value | G2: =+'Field Registry'!C15 -> PropertyType | H2: = | I2: =+tblPropertyType[[#This Row],[ListPropertyType]] -> Multifamily | K2: =+'Field Registry'!C20 -> InterestAppraised | L2: =+'Dropdown Lists'!E2 -> Fee Simple | M2: None
A3: R002 | B3: 100-Interest | C3: Interest Rule | D3: =+D2 -> Condition + Output | E3: And | F3: Set Value | H3: = | I3: =+tblPropertyType[[#This Row],[ListPropertyType]] -> Self-Storage | L3: =+'Dropdown Lists'!E2 -> Fee Simple | M3: None
A4: R003 | B4: 100-Interest | C4: Interest Rule | D4: Condition + Output | E4: And | F4: Set Value | H4: = | I4: =+tblPropertyType[[#This Row],[ListPropertyType]] -> Retail | L4: =+'Dropdown Lists'!E3 -> Leased Fee Interest | M4: None
A5: R004 | B5: 100-Interest | C5: Interest Rule | D5: Condition + Output | E5: And | F5: Set Value | H5: = | I5: =+tblPropertyType[[#This Row],[ListPropertyType]] -> Industrial | L5: =+'Dropdown Lists'!E3 -> Leased Fee Interest | M5: None
A6: R005 | B6: 100-Interest | C6: Interest Rule | D6: Condition + Output | E6: And | F6: Set Value | H6: = | I6: =+tblPropertyType[[#This Row],[ListPropertyType]] -> Office | L6: =+'Dropdown Lists'!E3 -> Leased Fee Interest | M6: None
A7: R006 | B7: 100-Interest | C7: Interest Rule | D7: Condition + Output | E7: And | F7: Set Value | H7: = | I7: =+tblPropertyType[[#This Row],[ListPropertyType]] -> Land | L7: =+'Dropdown Lists'!E2 -> Fee Simple | M7: None
A8: R007 | B8: 100-Interest | C8: Interest Rule | D8: Condition + Output | E8: And | F8: Set Value | H8: = | I8: =+tblPropertyType[[#This Row],[ListPropertyType]] -> Hotel | L8: =+L2 -> Fee Simple | M8: None
A9: R008 | B9: 100-Interest | C9: Interest Rule | D9: Condition + Output | E9: And | F9: Set Value | H9: = | I9: =+tblPropertyType[[#This Row],[ListPropertyType]] -> Seniors | L9: =+L2 -> Fee Simple | M9: None
A10: R009 | B10: 100-Interest | C10: Interest Rule | D10: Condition + Output | E10: And | F10: Set Value | G10: =+'Field Registry'!C17 -> Tenancy | H10: = | I10: Owner-Occupied | K10: InterestAppraised | L10: Fee Simple
H11: = | I11: Multi-Tenant | L11: Leased Fee Interest
H12: = | I12: Partial Owner Occupied | L12: Leasehold Estate
H13: = | I13: Single-Tenant | L13: Going Concern
H14: = | I14: Unkown
H15: = | I15: Vacant
A16: R010 | B16: 100-Interest | C16: Interest Rule | D16: Condition + Output | E16: And | F16: Set Value | G16: =+'Field Registry'!C16 -> PropertySubtype | H16: = | I16: =+'Dropdown Lists'!C4 -> Mixed Use | K16: InterestAppraised | L16: Fee Simple & Lease Fee | M16: None
A17: R011 | B17: 200-Scenario | C17: Scenario Rule | D17: Condition + Output | E17: And | F17: Add Value | G17: =+'Field Registry'!C19 -> StatusofImprovements | H17: = | I17: =+'Dropdown Lists'!I2 -> Existing - Completed | K17: =+'Field Registry'!C22 -> ValueScenarios | L17: =+'Dropdown Lists'!J6 -> As Stabilized | M17: None
A18: R012 | B18: 200-Scenario | C18: Scenario Rule | D18: Condition + Output | E18: And | F18: Add Value | H18: = | I18: =+'Dropdown Lists'!I3 -> Existing - Renovated | L18: =+'Dropdown Lists'!J6 -> As Stabilized | M18: None
A19: R013 | B19: 200-Scenario | C19: Scenario Rule | D19: Condition + Output | E19: And | F19: Add Value | H19: = | I19: =+'Dropdown Lists'!I4 -> Existing - Under Renovation | L19: As Is | M19: None
A20: R014 | B20: 200-Scenario | C20: Scenario Rule | D20: Condition + Output | E20: And | F20: Add Value | H20: = | I20: =+I19 -> Existing - Under Renovation | L20: As If Complete & Stabilized | M20: None
A21: R015 | B21: 200-Scenario | C21: Scenario Rule | D21: Condition + Output | E21: And | F21: Add Value | H21: = | I21: =+'Dropdown Lists'!I5 -> Existing - To Be Renovated | L21: As Is | M21: None
A22: R016 | B22: 200-Scenario | C22: Scenario Rule | D22: Condition + Output | E22: And | F22: Add Value | H22: = | I22: =+'Dropdown Lists'!I5 -> Existing - To Be Renovated | L22: =+L20 -> As If Complete & Stabilized | M22: None
A23: R017 | B23: 200-Scenario | C23: Scenario Rule | D23: Condition + Output | E23: And | F23: Add Value | H23: = | I23: =+'Dropdown Lists'!I6 -> Proposed - Vacant Land | L23: As Is Vacant Land | M23: None
A24: R018 | B24: 200-Scenario | C24: Scenario Rule | D24: Condition + Output | E24: And | F24: Add Value | H24: = | I24: =+I23 -> Proposed - Vacant Land | L24: As If Complete & Stabilized | M24: None
A25: R019 | B25: 200-Scenario | C25: Scenario Rule | D25: Condition + Output | E25: And | F25: Add Value | H25: = | I25: =+'Dropdown Lists'!I7 -> Proposed - Improved Land (Demolition Required) | L25: As If Vacant | M25: None
A26: R020 | B26: 200-Scenario | C26: Scenario Rule | D26: Condition + Output | E26: And | F26: Add Value | H26: = | I26: =+I25 -> Proposed - Improved Land (Demolition Required) | L26: As If Complete & Stabilized | M26: None
A27: R021 | B27: 200-Scenario | C27: Scenario Rule | D27: Condition + Output | E27: And | F27: Add Value | H27: = | I27: =+'Dropdown Lists'!I8 -> Proposed - Under Construction | L27: As If Vacant | M27: None
A28: R022 | B28: 200-Scenario | C28: Scenario Rule | D28: Condition + Output | E28: And | F28: Add Value | H28: = | I28: =+I27 -> Proposed - Under Construction | L28: As If Complete & Stabilized | M28: None
A29: R023 | B29: 200-Scenario | C29: Scenario Rule | D29: Condition + Output | E29: And | F29: Set Value | G29: AuthorizedUse | H29: = | I29: Insurance | L29: Insurable Replacement Cost | M29: None
A30: R024 | B30: 300-Approach | C30: Approach Rule | D30: Condition + Output | E30: And | F30: Add Value | G30: =+'Field Registry'!C22 -> ValueScenarios | H30: = | I30: =+'Dropdown Lists'!J6 -> As Stabilized | K30: =+'Field Registry'!C23 -> ApproachestoValue | L30: Direct Comparison | M30: None
A31: R025 | B31: 300-Approach | C31: Approach Rule | D31: Condition + Output | E31: And | F31: Add Value | G31: =+G30 -> ValueScenarios | H31: = | I31: As Stabilized | K31: =+K30 -> ApproachestoValue | L31: Income Approach | M31: None
A32: R026 | B32: 300-Approach | C32: Approach Rule | D32: Condition + Output | E32: And | F32: Add Value | G32: =+G31 -> ValueScenarios | H32: = | I32: As Is Vacant Land | K32: =+K31 -> ApproachestoValue | L32: =+'Dropdown Lists'!K2 -> Land Direct Comparison Approach | M32: None
A33: R027 | B33: 300-Approach | C33: Approach Rule | D33: Condition + Output | E33: And | F33: Add Value | G33: =+G32 -> ValueScenarios | H33: = | I33: =+'Dropdown Lists'!J3 -> As If Vacant Land | K33: =+K32 -> ApproachestoValue | L33: =+L32 -> Land Direct Comparison Approach | M33: None
A34: R028 | B34: 300-Approach | C34: Approach Rule | D34: Condition + Output | E34: And | F34: Add Value | G34: =+G33 -> ValueScenarios | H34: = | I34: =+'Dropdown Lists'!J4 -> As If Complete & Stabilized | K34: =+K33 -> ApproachestoValue | L34: =+'Dropdown Lists'!K3 -> Cost Approach | M34: None
C39: =+Types!L7 -> EA / HC Logic | F39: Insert EA/HC Text | G39: ValueScenarios | I39: =+'Dropdown Lists'!J3 -> As If Vacant Land | K39: EA Text | L39: N/A | M39: The As If Vacant market land value is developed under the hypothetical condition that the existing improvements on the subject site do not exist, and that the property is vacant as of the effective date. This condition is contrary to the known physical state of the property and is made for the purpose of estimating the underlying land value.
C40: =+C39 -> EA / HC Logic | F40: Insert EA/HC Text | G40: =+G39 -> ValueScenarios | I40: =+'Dropdown Lists'!J6 -> As Stabilized | K40: =+K39 -> EA Text | L40: =+L39 -> N/A

Sheet Text Library
A1: Narrative ID | B1: Narrative Type | C1: Narrative Name | D1: Text | E1: Used In
A2: EA-001 | B2: Extraordinary Assumption | C2: As If Vacant Demolition | D2: The As If Vacant market land value is developed under the hypothetical condition that the existing improvements on the subject site do not exist, and that the property is vacant as of the effective date. This condition is contrary to the known physical state of the property and is made for the purpose of estimating the underlying land value. | E2: Report | LOE
A3: EA-002 | B3: Extraordinary Assumption | C3: As If Vacant Demolition | D3: The As If Vacant market land value is developed under the hypothetical condition that the existing improvements on the subject site do not exist, and that the property is vacant as of the effective date. This condition is contrary to the known physical state of the property and is made for the purpose of estimating the underlying land value. | E3: Report | LOE

Sheet Types
A1: Operator | B1: Meaning | C1: Example | F1: Rule Role | H1: Logic Type | I1: Rule Types | J1: Purpose | L1: Rule Groups
A2: = | B2: Equals | C2: Property Type = Multifamily | F2: Condition | G2: IF | H2: And | I2: Set Value | J2: Calculate or assign values based on inputs | L2: Property Identification
A3: ≠ | B3: Not Equal | C3: Property Type ≠ Industrial | F3: Output | G3: Then | H3: Or | I3: Add Value ✅ | J3: Force a value (overwrite) | L3: State of Improvements
A4: IN | B4: One of several values | C4: Property Type IN (Multifamily, Self Storage) | F4: Condition + Output | G4: If Then | I4: Remove Value | J4: Add to multi-select field | L4: Valuation Premise
A5: NOT IN | B5: Not one of several values | C5: Property Type NOT IN (Retail, Office) | I5: Replace Text | J5: Remove from multi-select | L5: Valuation Scenario
A6: > | B6: Greater than | C6: Unit Count > 100 | I6: Append Text | L6: Approaches to Value
A7: < | B7: Less than | C7: Building Size < 10,000 | I7: Calculate | L7: EA / HC Logic
A8: ≥ | B8: Greater than or equal | C8: Site Area ≥ 1 acre | I8: Show | L8: Inspection Logic
A9: ≤ | B9: Less than or equal | C9: Vacancy Rate ≤ 5% | I9: Hide | L9: Scope of Work (LOE)
A10: CONTAINS | B10: Text contains value | C10: Address CONTAINS “Calgary” | L10: Report Narrative
A11: IS EMPTY | B11: No value entered | C11: Pro Forma IS EMPTY | L11: Data Collection
A12: IS NOT EMPTY | B12: Value exists | C12: Inspection Date IS NOT EMPTY | L12: Fee Calculation
L13: Invoice Generation
L14: Workflow Automation
L15: System Integration
L16: Validation
E18: Action
E19: Set | I19: Show
E20: Add | I20: Hide
E21: Remove | I21: Trigger
E22: Append Text | I22: Validation Rule | J22: Enforce correctness / block submission
E23: Replace Text | I23: Conditional Required | J23: Make a field required
E24: Calculate
E25: Show | I25: Workflow Trigger | J25: Create tasks, statuses, notifications
E26: Hide | I26: Narrative Generation | J26: Output text
E27: Trigger | I27: Document Output | J27: Control what appears in LOE/report
I28: Integration Trigger | J28: Push to external systems

Sheet Valcre Fields
A1: Valcre Job Field Name | B1: Valcre Job Field Label | C1: Valcre Contact Field Name | D1: Valcre Contact Field Label | E1: Valcre Property Field Name | F1: Valcre Property Field Label | G1: Valcre Building Field Name | H1: Valcre Building Field Label | I1: Valcre Parcel Assessment Field Name | J1: Valcre Parcel Assessment Field Label | K1: Valcre Parcel Field Name | L1: Valcre Parcel Field Label
A2: Job ID | B2: Id | C2: Contact ID | D2: Id | E2: Property ID | F2: Id | G2: Id | H2: Id | I2: Id | J2: Id | K2: Id | L2: Id
A3: Job Number | B3: Number | C3: Company Name | D3: Company | E3: Name | F3: Name | G3: Building Name | H3: Name | I3: Year | J3: Year | K3: Parcel number | L3: Number
A4: Job Name | B4: Name | C4: Main Phone | D4: CompanyPhoneNumber | E4: Street Address | F4: AddressStreet | G4: Comments | H4: Comments | I4: Land | J4: LandValue | K4: Legal description | L4: LegalDescription
A5: Client File Number | B5: ClientRef | C5: Main Fax | D5: CompanyFaxNumber | E5: Unit | F5: AddressStreet2 | G5: Year Built | H5: YearBuilt | I5: Improved | J5: ImprovedValue | K5: Primary land | L5: PrimaryArea
A6: Borrower | B6: Borrower | C6: Website | D6: CompanyWebsite | E6: City | F6: AddressCity | G6: Year Renovated | H6: YearRenovated | I6: Exemptions | J6: Exemptions | K6: Excess land | L6: ExcessArea
A7: Status | B7: Status | C7: Company Type | D7: CompanyType | E7: State/Province | F7: AddressState | G7: Dock Doors | H7: DockDoorCount | I7: Total | J7: TotalValue | K7: Surplus land | L7: SurplusArea
A8: Fee | B8: Fee | C8: Street Address | D8: AddressStreet | E8: ZIP/Postal | F8: AddressPostalCode | G8: Grade Doors | H8: GradeDoorCount | I8: Taxes | J8: Taxes | K8: Unusable land | L8: UnusableArea
A9: Retainer | B9: Retainer | C9: Unit | D9: AddressStreet2 | E9: Country | F9: AddressCountry | G9: Rail Doors | H9: RailDoorCount | I9: ParcelId | J9: ParcelId | K9: UsableArea | L9: UsableArea
A10: Amount Paid | B10: AmountPaid | C10: City | D10: AddressCity | E10: Region | F10: AddressCounty | G10: Cross Docks | H10: CrossDockCount | I10: Created | J10: CreatedTime | K10: GrossArea | L10: GrossArea
A11: Check Number | B11: CheckNumber | C11: State/Province | D11: AddressState | E11: Market Name | F11: Market | G11: Levelers | H11: HasLevelers | I11: Updated | J11: ModifiedTime | K11: AssessedValue | L11: AssessedValue
A12: Appraised Value | B12: AppraisedValue | C12: ZIP/Postal | D12: AddressPostalCode | E12: Submarket | F12: SubmarketName | G12: Clear Height | H12: ClearHeightComments | I12: Display Name | J12: _DisplayName | K12: Taxes | L12: Taxes
... A14: Awarded Date | B14: AwardDate | C14: Last Name | D14: LastName | E14: Longitude | F14: Longitude | G14: Maneuverability | H14: ManeuverabilityComments | I14: CustomFields | J14: _DisplayName | K14: PropertyId | L14: PropertyId
A15: Due Date | B15: DueDate | C15: Title | D15: Title | E15: Property Type | F15: Types | G15: Number of Floors | H15: FloorCount | K15: Created | L15: CreatedTime
A16: Internal Due Date | B16: InternalDueDate | C16: Phone | D16: PhoneNumber | E16: Subtype | F16: SecondaryType | G16: Building Class | H16: ClassComments | K16: Updated | L16: ModifiedTime
A17: Invoice Date | B17: InvoiceDate | C17: Mobile | D17: CellNumber | E17: Parcel ID | F17: ParcelNumbers | G17: Foundation | H17: FoundationComments | K17: Display Name | L17: _DisplayName
A18: Inspection Date | B18: InspectionDate | C18: Email | D18: Email | E18: Number of Parcels | F18: ParcelCount | G18: Exterior Walls/Framing | H18: ExteriorWallComments | K18: LatestAssessment | L18: LatestAssessment._DisplayName
A19: Paid Date | B19: PaidDate | C19: Salutation | D19: Salutation | E19: Land Area (AC) | F19: LandAreaAC | G19: Roof | H19: RoofComments | K19: Property | L19: Property._DisplayName
A20: Date of Value | B20: EffectiveDate | C20: Suffix | D20: Suffix | E20: Land Area | F20: LandAreaSF | G20: Elevators | H20: ElevatorComments | K20: Assessments | L20: _DisplayName
A21: Format | B21: ReportFormat | C21: Division | D21: Division | E21: Buildable Area | F21: BuildableArea | G21: HVAC | H21: HvacComments | K21: PropertyDemographics | L21: _DisplayName
A22: Authorized Use | B22: IntendedUses | C22: Extension | D22: Extension | E22: Zone Name | F22: ZoningName | G22: Insulation | H22: InsulationComments | K22: Files | L22: _DisplayName
A23: Scope | B23: Scopes | C23: Fax | D23: FaxNumber | E23: Zoning | F23: Zoning | G23: Lighting | H23: LightingComments | K23: CustomFields | L23: _DisplayName
A24: Analysis Level | B24: AnalysisLevel | C24: Notes | D24: Comments | E24: Shape | F24: SiteShape | G24: Electrical | H24: ElectricalComments
A25: Purpose | B25: Purposes | C25: Confidential | D25: Privacy | E25: Topography | F25: SiteTopography | G25: Interior Walls | H25: InteriorWallComments
A26: Values | B26: RequestedValues | C26: Name | D26: Name | E26: Site Grade | F26: SiteGrade | G26: Doors and Windows | H26: DoorAndWindowComments
A27: Staff 1 Role | B27: Staff1Role | C27: Address | D27: FullAddress | E27: Corner | F27: SiteCorner | G27: Ceilings | H27: CeilingComments
A28: Staff 2 Role | B28: Staff2Role | C28: Address | D28: FullAddressMultiLine | E28: Density | F28: Density | G28: Plumbing | H28: PlumbingComments
A29: Staff 3 Role | B29: Staff3Role | C29: Contact | D29: FullContactInformation | E29: Permitted FAR | F29: PermittedFAR | G29: Floor Coverings | H29: FloorComments
A30: Confidential | B30: Privacy | C30: Created | D30: CreatedTime | E30: Permitted Building Height | F30: PermittedBuildingHeight | G30: Fire Safety | H30: SafetyFeaturesComments
A31: General | B31: Comments | C31: Updated | D31: ModifiedTime | E31: Proposed Land Use | F31: ProposedLandUse | G31: Interior Finish/Build-Out | H31: InteriorFinishComments
A32: Client | B32: ClientComments | C32: Display Name | D32: _DisplayName | E32: Site H&BU | F32: SiteHBU | G32: Site Improvements | H32: SiteImprovementComments
A33: Delivery | B33: DeliveryComments | C33: Office | D33: Office._DisplayName | E33: Off-Site Improvements | F33: OffSiteImprovements | G33: Deferred Maintenance | H33: DeferredMaintenanceComments
A34: Payment | B34: PaymentComments | C34: Relationship Owner | D34: Owner._DisplayName | E34: View | F34: SiteView | G34: Gross Building Area (GBA) | H34: GrossBuildingArea
A35: Amount Outstanding | B35: AmountOutstanding | C35: Files | D35: _DisplayName | E35: Utilities | F35: Utilities | G35: Net Rentable Area (NRA) | H35: NetRentableArea
A36: Days Sales Outstanding | B36: DaysToPaid | C36: CustomFields | D36: _DisplayName | E36: Easements | F36: Easements | G36: First Floor Footprint (SF) | H36: FootprintArea
A37: Aging | B37: DaysSinceInvoiced | E37: Entitlements | F37: Entitlements | G37: Finished Basement (SF) | H37: FinishedBasementArea
A38: Appraisers | B38: StaffAppraisers | E38: Environmental | F38: EnvironmentalIssues | G38: Unfinished Basement (SF) | H38: UnfinishedBasementArea
A39: Assistants | B39: StaffAssistants | E39: Frontage | F39: Frontage | G39: Warehouse Area (SF) | H39: WarehouseArea
A40: Procurers | B40: StaffProcurers | E40: Flood Zones | F40: SiteFloodZone | G40: Office Area (SF) | H40: OfficeArea
A41: Reviewers | B41: StaffReviewers | E41: Project Design | F41: ProjectDesign | G41: Office Buildout | H41: OfficeBuildoutRatio
...
