Workbook
Name ListAssignmentType: 'Dropdown Lists'!$Q$2:$Q$3
Name ListAuthorizedUse: 'Dropdown Lists'!$F$2:$F$9
Name ListDataControlType: 'Dropdown Lists'!$AB$2:$AB$11
Name ListInterestAppraised: 'Dropdown Lists'!$E$2:$E$5
Name ListOutputType: 'Dropdown Lists'!$Z$2:$Z$10
Name ListPropertySubtype: 'Dropdown Lists'!$C$2:$C$4
Name ListPropertyType: 'Dropdown Lists'!$B$2:$B$10
Name ListStateofImprovements: 'Dropdown Lists'!$H$2:$H$3
Name ListValuationScenario: 'Dropdown Lists'!$M$2:$M$4
Name ListYesNo: 'Dropdown Lists'!$AC$2:$AC$3

Sheet Field Registry
C1: VALTA Field Name | D1: VALTA Field Label/UI | E1: Data Control Type | F1: Source Type | G1: Dropdown List | H1: New Custom Valcre Field | I1: Required | J1: App Location | K1: Valcre Field Name | L1: Valcre Field Label/UI | M1: Valcre Field ID | N1: Valcre Record Location | O1: Valcre Field Key (API) | P1: Used In Outputs | Q1: Description | R1: Owner | S1: Status
C2: JobNumber | D2: Job Number | E2: Alpha Numeric | F2: Valcre API | H2: No | I2: Yes | K2: Number | L2: Job Number | N2: Job
C3: JobName | D3: Job Name | E3: Alpha Numeric | F3: User Input | H3: No | I3: Yes | K3: Name | L3: Job Name | N3: Job
C4: JobStatus | D4: Job Status | E4: Select one option | F4: User Input | H4: No | I4: Yes | K4: Status | L4: Status | N4: Job
C5: SubjectProperty | D5: Subject Property | E5: Alpha Numeric | F5: Valcre API | H5: No | I5: Yes | K5: Subject Property | L5: Property._DisplayName | N5: Job
C6: ClientCompanyName | D6: Client Company Name | E6: Alpha Numeric | F6: User Input | H6: No | I6: Yes | K6: Client | L6: Client._DisplayName | N6: Job
C7: ClientOrganizationAddress | D7: Client Organization Address | E7: Alpha Numeric | F7: User Input | H7: No | I7: Yes | K7: Various | L7: Various | N7: Contact
C8: ClientFirstName | D8: Client First Name | E8: Text | F8: User Input | H8: No | I8: Yes | K8: First Name | L8: FirstName | N8: Contact
C9: ClientLastName | D9: Client Last Name | E9: Text | F9: User Input | H9: No | I9: Yes | K9: Last Name | L9: LastName | N9: Contact
C10: ClientTitle | D10: Client Title | E10: Text | F10: User Input | H10: No | I10: Yes | K10: Title | L10: Title | N10: Contact
C11: ClientPhone | D11: Client Phone | E11: Text | F11: User Input | H11: No | I11: Yes | K11: Phone | L11: PhoneNumber | N11: Contact
C12: ClientEmail | D12: Client Email | E12: Text | F12: User Input | H12: No | I12: Yes | K12: Email | L12: Email | N12: Contact
C13: PropertyName | D13: Property Name | E13: Alpha Numeric | F13: User Input | H13: No | I13: Yes | K13: Name | L13: Name | N13: Property
... C16: PropertySubtype | D16: Property Subtype | E16: Select one option | F16: User Input | H16: No | I16: No | K16: Subtype | L16: SecondaryType | N16: Property
C17: Tenancy | D17: Tenancy | E17: Select one option | F17: User Input | G17: ListTenancy | H17: Yes | I17: No | K17: Tenancy | M17: 12408 | N17: Job custom field | O17: 12408 | Q17: NOTE: option "Unkown" created verbatim per client master (D3) — client can correct spelling later.
C18: StateofImprovements | D18: State of Improvements | E18: Select one option | F18: User Input | G18: ListSateofImprovements | H18: Yes | I18: No | K18: StateofImprovements | M18: 12409 | N18: Job custom field | O18: 12409
C19: StatusofImprovements | D19: Status of Improvements | E19: Select one option | F19: User Input | G19: ListSatusofImprovements | H19: Yes | I19: No | K19: StatusofImprovements | M19: 12407 | N19: Job custom field | O19: 12407
C20: CurrentUseImprovements | D20: Current Use Improvements | E20: Select one option | F20: User Input | G20: =+'Dropdown Lists'!K1 | H20: Yes | I20: Yes | K20: CurrentUseImprovements | M20: 12410 | N20: Job custom field | O20: 12410
C21: ProposedUseImprovements | D21: Proposed Use Improvements | E21: Select one option | F21: User Input | G21: =+'Dropdown Lists'!L1 | H21: Yes | I21: Yes | K21: ProposedUseImprovements | M21: 12411 | N21: Job custom field | O21: 12411
C22: InterestAppraised | D22: Interest Appraised | E22: Select multiple options | F22: User Input | G22: ListInterestAppraised | H22: Yes | I22: Yes | K22: InterestAppraised | M22: 12412 | N22: Job custom field | O22: 12412
C23: AuthorizedUse | D23: Authorized Use | E23: Select one option | F23: User Input | G23: ListAuthorizedUse | H23: Yes | I23: Yes | K23: AuthorizedUse | M23: 12413 | N23: Job custom field | O23: 12413
C24: ValueScenarios | D24: Value Scenario (s) | E24: Select multiple options | F24: User Input | G24: ListValueScenarios | H24: Yes | I24: Yes | K24: ValueScenarios | M24: 12414 | N24: Job custom field | O24: 12414
C25: ApproachestoValue | D25: Approaches to Value | E25: Select multiple options | F25: User Input | G25: ListApproachestoValue | H25: Yes | I25: Yes | K25: ApproachestoValue | M25: 12415 | N25: Job custom field | O25: 12415
C26: AssignmentType | D26: Assignment Type | E26: Select one option | F26: User Input | G26: ListAssignmentType | H26: Yes | I26: Yes | K26: AssignmentType | M26: 12416 | N26: Job custom field | O26: 12416
C27: ReportType | D27: Report Type | E27: Select one option | F27: User Input | G27: ListReportType | H27: Yes | I27: Yes | K27: ReportType | M27: 12417 | N27: Job custom field | O27: 12417
B28: Delete | C28: DesktopReport | D28: Desktop Report | E28: Select one option | F28: User Input | G28: ListYes/No | H28: Yes | I28: Yes | K28: DesktopReport | M28: 12418 | N28: Job custom field | O28: 12418
C29: Valuetimeframe | D29: Value Timeframe | E29: Select one option | F29: User Input | G29: ListValueTimeFrame | H29: Yes | I29: Yes | K29: Valuetimeframe | M29: 12419 | N29: Job custom field | O29: 12419
C30: InspectionDate | D30: Inspection Date | E30: Date | F30: User Input | H30: No | I30: No | K30: InspectionDate | L30: Inspection Date | N30: Job
C31: Fee | D31: Fee | E31: Whole Number | F31: Calculated | H31: No | I31: Yes | K31: Fee | L31: Fee | N31: Job
C32: DeliveryTime | D32: Delivery Time | E32: Whole Number | F32: User Input | H32: Yes | I32: Yes | K32: DeliveryTime | M32: 12420 | N32: Job custom field | O32: 12420
C33: PaidDate | D33: Paid Date | E33: Date | F33: Logic | H33: No | I33: No | K33: PaidDate | L33: Paid Date | N33: Job
C34: Paid | D34: Paid | E34: Checkbox | F34: Logic | H34: Yes | I34: No | K34: Paid | M34: 12421 | N34: Job custom field | O34: 12421
C35: RequestDate | D35: Request Date | E35: Date | F35: Logic | H35: No | I35: No | K35: BidDate | L35: Bid Date | N35: Job
C36: SignedDate | D36: Signed Date | E36: Date | F36: Logic | H36: No | I36: No | K36: AwardDate | L36: Awarded Date | N36: Job
C37: DueDate | D37: Due Date | E37: Date | F37: Logic | H37: No | I37: No | K37: DueDate | L37: Due Date | N37: Job
C38: AmountPaid | D38: Amount Paid | E38: Decimal | F38: Logic | H38: No | I38: No | K38: AmountPaid | L38: Amount Paid | N38: Job
C39: ClientDocuments | D39: Client Documents | E39: Select multiple options | F39: Logic | G39: ListClientDocuments | H39: Yes | I39: Yes | K39: ClientDocuments | M39: 12422 | N39: Job custom field | O39: 12422
C40: PreviouslyAppraised | D40: Previously Appraised | E40: Select one option | F40: User Input | G40: ListYes/No | H40: Yes | I40: No | K40: PreviouslyAppraised | M40: 12423 | N40: Job custom field | O40: 12423
C41: TransactionStatus | D41: Transaction Status | E41: Select multiple options | F41: User Input | G41: ListTransactionStatus | H41: Yes | I41: Yes | K41: TransactionStatus | M41: 12424 | N41: Job custom field | O41: 12424
C42: ZoningStatus | D42: Zoning Status | E42: Select one option | F42: User Input | G42: ListZoningStatus | H42: Yes | I42: No | K42: ZoningStatus | M42: 12425 | N42: Job custom field | O42: 12425
...

Sheet Dropdown Lists
A1: DropdownLists | B1: ListPropertyType | C1: ListPropertySubtype | D1: ListTenancy | E1: ListInterestAppraised | F1: ListAuthorizedUse | G1: ListValueTimeFrame | H1: ListSateofImprovements | I1: ListSatusofImprovements | J1: ListStateText | K1: ListCurrentUseImprovements | L1: ListProposedUseImprovements | M1: ListValueScenarios | N1: ListApproachestoValue | O1: ListMethod | P1: ListReportType | Q1: ListAssignmentType | R1: ListTransactionStatus | S1: ListClientDocuments | T1: ListZoningStatus | U1: ListLand$/Metric | Y1: ListSourceType | Z1: ListOutputType | AA1: ListValcreRecordLocation | AB1: ListDataControlType | AC1: ListYes/No | AD1: ListOutputLocation | AE1: Used In Excel | AF1: Used In Word
A2: ListApproachestoValue | B2: Multifamily | C2: Apartment | D2: Multi-Tenant | E2: Fee Simple | F2: First Mortgage Financing | G2: Current | H2: Improved | I2: Improved - Completed | J2: as improved | K2: Vacant Land | L2: Not Applicable | M2: As Is Vacant Land | N2: Land Direct Comparison Approach | O2: Direct Capitalization Method | P2: Comprehensive | Q2: Single Property | R2: Not Applicable | S2: Previous Appraisal | T2: In Place | U2: $/Unit | Y2: User Input | Z2: LOE | AA2: Job | AB2: Text | AC2: Yes | AE2: HOME | AF2: LOT
A3: ListAssignmentType | B3: Self-Storage | C3: Townhouse | D3: Owner Occupied | E3: Leased Fee Interest | F3: Financial Reporting | G3: Prospective | H3: Proposed | I3: Improved - Renovated | J3: as proposed | K3: Single Family | L3: Single Family | M3: As If Vacant Land | N3: Cost Approach | O3: Discounted Cash Flow Method | P3: Concise | Q3: Multiple Properties | R3: Listed | S3: Property Details | T3: To Be Rezoned | U3: $/FAR | Y3: Valcre API | Z3: Excel | AA3: Contact | AB3: Multiple lines of text | AC3: No | AE3: EXEC | AF3: Exec Summ
A4: ListAuthorizedUse | B4: Retail | C4: Mixed Use | D4: Partial Owner Occupied | E4: Leasehold Estate | F4: Insurance | G4: Retrospective | H4: Vacant Land | I4: Improved - Under Renovation | K4: Multifamily | L4: Multifamily | M4: As If Complete & Stabilized | N4: Direct Comparison Approach | P4: Form | R4: Under Contract | S4: Proforma | U4: $/SF | Y4: Calculated | Z4: Word | AA4: Property | AB4: Whole Number | AE4: MAP
A5: ListClientDocuments | B5: Industrial | C5: Shopping Centre | D5: Single-Tenant | E5: Going Concern | F5: Internal Decision-Making | H5: Improved Development Land | I5: Improved - Proposed Renovation | K5: Retail | L5: Mixed Use | M5: As-Is | N5: Income Approach | S5: Unit Mix | U5: $/Acre | Y5: Logic | Z5: LOR | AA5: Building | AB5: Decimal | AE5: IMPRV
A6: ListDataControlType | B6: Office | D6: Unkown | F6: Acquisition-Disposition | I6: Proposed - Vacant Land | K6: Industrial | L6: Retail | M6: As Stabilized | S6: Rent Roll | Z6: ClickUP | AA6: Parcel | AB6: Select one option
A7: ListInterestAppraised | B7: Land | D7: Vacant | F7: Estate Planning | I7: Proposed - Improved Land (Demolition Required) | K7: Office | L7: Industrial | M7: As If Complete & Stabilized - Renovated | S7: Historical Operating Expenses | Z7: QBO | AB7: Select multiple options
A8: ListLand$/Metric | B8: Hotel | F8: Litigation | I8: Proposed - Under Construction | L8: Office | M8: As If Complete - Rezoned | S8: Development Permit Drawings | Z8: LOE, Excel, Word | AB8: Checkbox
A9: ListMethod | B9: Seniors | F9: GST | M9: As If Complete - Serviced | S9: Contact for Property Tour | Z9: LOR, Excel, Word, CU | AB9: Date
A10: ListOutputLocation | B10: Other | M10: As If Complete - Subdivided | S10: Purchase & Sale Agreement | Z10: LOE, Excel, Word, LOR, CU | AB10: Calculation
A11: ListOutputType | M11: Insurable Replacement Cost | S11: Environmental Reports | Z11: LOE, Excel, Word, LOR, CU, QBO | AB11: Alpha Numeric
A12: ListPropertySubtype | S12: Property Condition Reports
A13: ListPropertyType
A14: ListReportType
A15: ListSateofImprovements
A16: ListSatusofImprovements
A17: ListSourceType
A18: ListTenancy
A19: ListTransactionStatus
A20: ListValcreRecordLocation
A21: ListValueScenarios
A22: ListValueTimeFrame
A23: ListYes/No
A24: ListZoningStatus

Sheet EA-HC Text
A1: Number | B1: =+'Field Registry'!C24 | C1: ListEA/HCSummary | D1: ListEADetail | E1: ListHCDetail
A2: 1 | B2: =+'Dropdown Lists'!M2 | C2: current market value of the subject property as of the effective date | D2: None | E2: None
A3: 2 | B3: =+'Dropdown Lists'!M3 | C3: current makret value based on the extraordinary assumption and hypothetical condition that the existing improvements on the subject site do not exist, and that the property is vacant as of the effective date. | D3: The As If Vacant market land value is developed under the extraordinary assumption that the existing improvements on the subject site do not exist, and that the property is vacant as of the effective date. This assumption is contrary to the known physical state of the property and is made for the purpose of estimating the underlying land value. | E3: The As If Vacant market land value is developed under the hypothetical condition that the existing improvements on the subject site do not exist, and that the property is vacant as of the effective date. This condition is contrary to the known physical state of the property and is made for the purpose of estimating the underlying land value.
A4: 3 | B4: =+'Dropdown Lists'!M4 | C4: current market value of the subject property as proposed based upon the extraordinary assumption and hypothetical condition that the project is 100% complete and fully leased at market rents and is at stabilized occupancy, as of the effective date. | D4: The As If Vacant market land value is developed under the extraordinary assumption that the existing improvements on the subject site do not exist, and that the property is vacant as of the effective date. This assumption is contrary to the known physical state of the property and is made for the purpose of estimating the underlying land value. | E4: The As If Vacant market land value is developed under the hypothetical condition that the existing improvements on the subject site do not exist, and that the property is vacant as of the effective date. This condition is contrary to the known physical state of the property and is made for the purpose of estimating the underlying land value.
A5: 4 | B5: =+'Dropdown Lists'!M5 | C5: current market value of the subject property as improved as of the effective date | D5: None | E5: None
A6: 5 | B6: =+'Dropdown Lists'!M6 | C6: current market value of the subject property based on the extraordinary assumption that the subject property is fully leased at market rents and is at stabilized occupancy as of the effective date. | D6: The As Stabilized value has been developed based on the extraordinary assumption that the subject property is fully leased at prevailing market rents and has achieved stabilized occupancy as of the effective date of the appraisal. Under this premise, no deductions are made for holding costs, rent loss, or lease-up expenses. In addition it is an extraordinary assumption that all units could achieve current market rent levels and stabilized occupancy as of the effective date. In reality, as of the effective date, the property's existing lease terms reflect contract rents that are deemed to be below-market rents. For the purposes of this analysis, it is assumed that lease-up to market rent levels has occurred under typical market conditions, without undue delay or concessions exceeding market norms. If this assumption proves incorrect, such as market rents are not achievable the value conclusion may be materially impacted. | E6: The As Stabilized value has been developed based on the hypothetical condition that the subject property is fully leased at prevailing market rents and has achieved stabilized occupancy as of the effective date of the appraisal. Under this premise, no deductions are made for holding costs, rent loss, or lease-up expenses. In addition it is a hypothetical condition that all units could achieve current market rent levels and stabilized occupancy as of the effective date. In reality, as of the effective date, the property's existing lease terms reflect contract rents that are deemed to be below-market rents. For the purposes of this analysis, it is assumed that lease-up to market rent levels has occurred under typical market conditions, without undue delay or concessions exceeding market norms. If this hypothetical condition proves incorrect, such as market rents are not achievable the value conclusion may be materially impacted.
A7: 6 | B7: =+'Dropdown Lists'!M7 | C7: current market value of the subject property as proposed based upon the extraordinary assumption and hypothetical condition that the renovation is 100% complete and the property is fully leased and is at stabilized occupancy, as of the effective date. | D7: The As If Renovated & Stabilized market value concluded herein has been developed under the extraordinary assumption that the existing improvements, as described in this report, have been fully renovated and have been leased at market rents with stabilized occupancy as of the effective date. In reality, the renovations are not complete as of the effective date. This appraisal does not consider unforeseeable events that could affect the timing, cost, or outcome of the renovation and lease-up process. If the stated hypothetical condition does not hold true, the value conclusion presented herein may be materially affected. | E7: The As If Renovated & Stabilized market value concluded herein has been developed under the hypothetical condition that the existing improvements, as described in this report, have been fully renovated and have been leased at market rents with stabilized occupancy as of the effective date. In reality, the renovations are not complete as of the effective date. This appraisal does not consider unforeseeable events that could affect the timing, cost, or outcome of the renovation and lease-up process. If the stated hypothetical condition does not hold true, the value conclusion presented herein may be materially affected.
B8: =+'Dropdown Lists'!M8
B9: =+'Dropdown Lists'!M9
B10: =+'Dropdown Lists'!M10
B11: =+'Dropdown Lists'!M11

Sheet Types
A1: Operator | B1: Meaning | C1: Example | F1: Rule Role | H1: Logic Type | I1: Rule Types | J1: Purpose | L1: Rule Groups
A2: = | B2: Equals | C2: Property Type = Multifamily | F2: Condition | G2: IF | H2: And | I2: Set Value | J2: Calculate or assign values based on inputs | L2: Property Identification
A3: ≠ | B3: Not Equal | C3: Property Type ≠ Industrial | F3: Output | G3: Then | H3: Or | I3: Add Value ✅ | J3: Force a value (overwrite) | L3: State of Improvements
A4: IN | B4: One of several values | C4: Property Type IN (Multifamily, Self Storage) | F4: Condition + Output | G4: If Then | I4: Remove Value | J4: Add to multi-select field | L4: Valuation Premise
A5: NOT IN | B5: Not one of several values | C5: Property Type NOT IN (Retail, Office) | I5: Replace Text | J5: Remove from multi-select | L5: Valuation Scenario
A6: > | B6: Greater than | C6: Unit Count > 100 | I6: Append Text | L6: Approaches to Value
A7: < | B7: Less than | C7: Building Size < 10,000 | I7: Calculate | L7: EA / HC Logic
A8: ≥ | B8: Greater than or equal | C8: Site Area ≥ 1 acre | I8: Show | L8: Inspection Logic
A9: ≤ | B9: Less than or equal | C9: Vacancy Rate ≤ 5% | I9: Hide | L9: Scope of Work (LOE)
A10: CONTAINS | B10: Text contains value | C10: Address CONTAINS “Calgary” | L10: Report Narrative
A11: IS EMPTY | B11: No value entered | C11: Pro Forma IS EMPTY | L11: Data Collection
A12: IS NOT EMPTY | B12: Value exists | C12: Inspection Date IS NOT EMPTY | L12: Fee Calculation
L13: Invoice Generation
L14: Workflow Automation
L15: System Integration
L16: Validation
E18: Action
E19: Set | I19: Show
E20: Add | I20: Hide
E21: Remove | I21: Trigger
E22: Append Text | I22: Validation Rule | J22: Enforce correctness / block submission
E23: Replace Text | I23: Conditional Required | J23: Make a field required
E24: Calculate
E25: Show | I25: Workflow Trigger | J25: Create tasks, statuses, notifications
E26: Hide | I26: Narrative Generation | J26: Output text
E27: Trigger | I27: Document Output | J27: Control what appears in LOE/report
I28: Integration Trigger | J28: Push to external systems

Sheet Valcre Fields
A1: Job Field Name | B1: Job Field Label | C1: Contact Field Name | D1: Contact Field Label | E1: Property Field Name | F1: Property Field Label | G1: Building Field Name | H1: Building Field Label | I1: Parcel Assessment Field Name | J1: Parcel Assessment Field Label | K1: Parcel Field Name | L1: Parcel Field Label
A2: Job ID | B2: Id | C2: Contact ID | D2: Id | E2: Property ID | F2: Id | G2: Id | H2: Id | I2: Id | J2: Id | K2: Id | L2: Id
A3: Job Number | B3: Number | C3: Company Name | D3: Company | E3: Name | F3: Name | G3: Building Name | H3: Name | I3: Year | J3: Year | K3: Parcel number | L3: Number
A4: Job Name | B4: Name | C4: Main Phone | D4: CompanyPhoneNumber | E4: Street Address | F4: AddressStreet | G4: Comments | H4: Comments | I4: Land | J4: LandValue | K4: Legal description | L4: LegalDescription
A5: Client File Number | B5: ClientRef | C5: Main Fax | D5: CompanyFaxNumber | E5: Unit | F5: AddressStreet2 | G5: Year Built | H5: YearBuilt | I5: Improved | J5: ImprovedValue | K5: Primary land | L5: PrimaryArea
A6: Borrower | B6: Borrower | C6: Website | D6: CompanyWebsite | E6: City | F6: AddressCity | G6: Year Renovated | H6: YearRenovated | I6: Exemptions | J6: Exemptions | K6: Excess land | L6: ExcessArea
A7: Status | B7: Status | C7: Company Type | D7: CompanyType | E7: State/Province | F7: AddressState | G7: Dock Doors | H7: DockDoorCount | I7: Total | J7: TotalValue | K7: Surplus land | L7: SurplusArea
A8: Fee | B8: Fee | C8: Street Address | D8: AddressStreet | E8: ZIP/Postal | F8: AddressPostalCode | G8: Grade Doors | H8: GradeDoorCount | I8: Taxes | J8: Taxes | K8: Unusable land | L8: UnusableArea
A9: Retainer | B9: Retainer | C9: Unit | D9: AddressStreet2 | E9: Country | F9: AddressCountry | G9: Rail Doors | H9: RailDoorCount | I9: ParcelId | J9: ParcelId | K9: UsableArea | L9: UsableArea
A10: Amount Paid | B10: AmountPaid | C10: City | D10: AddressCity | E10: Region | F10: AddressCounty | G10: Cross Docks | H10: CrossDockCount | I10: Created | J10: CreatedTime | K10: GrossArea | L10: GrossArea
A11: Check Number | B11: CheckNumber | C11: State/Province | D11: AddressState | E11: Market Name | F11: Market | G11: Levelers | H11: HasLevelers | I11: Updated | J11: ModifiedTime | K11: AssessedValue | L11: AssessedValue
A12: Appraised Value | B12: AppraisedValue | C12: ZIP/Postal | D12: AddressPostalCode | E12: Submarket | F12: SubmarketName | G12: Clear Height | H12: ClearHeightComments | I12: Display Name | J12: _DisplayName | K12: Taxes | L12: Taxes
... A14: Awarded Date | B14: AwardDate | C14: Last Name | D14: LastName | E14: Longitude | F14: Longitude | G14: Maneuverability | H14: ManeuverabilityComments | I14: CustomFields | J14: _DisplayName | K14: PropertyId | L14: PropertyId
A15: Due Date | B15: DueDate | C15: Title | D15: Title | E15: Property Type | F15: Types | G15: Number of Floors | H15: FloorCount | K15: Created | L15: CreatedTime
A16: Internal Due Date | B16: InternalDueDate | C16: Phone | D16: PhoneNumber | E16: Subtype | F16: SecondaryType | G16: Building Class | H16: ClassComments | K16: Updated | L16: ModifiedTime
A17: Invoice Date | B17: InvoiceDate | C17: Mobile | D17: CellNumber | E17: Parcel ID | F17: ParcelNumbers | G17: Foundation | H17: FoundationComments | K17: Display Name | L17: _DisplayName
A18: Inspection Date | B18: InspectionDate | C18: Email | D18: Email | E18: Number of Parcels | F18: ParcelCount | G18: Exterior Walls/Framing | H18: ExteriorWallComments | K18: LatestAssessment | L18: LatestAssessment._DisplayName
A19: Paid Date | B19: PaidDate | C19: Salutation | D19: Salutation | E19: Land Area (AC) | F19: LandAreaAC | G19: Roof | H19: RoofComments | K19: Property | L19: Property._DisplayName
A20: Date of Value | B20: EffectiveDate | C20: Suffix | D20: Suffix | E20: Land Area | F20: LandAreaSF | G20: Elevators | H20: ElevatorComments | K20: Assessments | L20: _DisplayName
A21: Format | B21: ReportFormat | C21: Division | D21: Division | E21: Buildable Area | F21: BuildableArea | G21: HVAC | H21: HvacComments | K21: PropertyDemographics | L21: _DisplayName
A22: Authorized Use | B22: IntendedUses | C22: Extension | D22: Extension | E22: Zone Name | F22: ZoningName | G22: Insulation | H22: InsulationComments | K22: Files | L22: _DisplayName
A23: Scope | B23: Scopes | C23: Fax | D23: FaxNumber | E23: Zoning | F23: Zoning | G23: Lighting | H23: LightingComments | K23: CustomFields | L23: _DisplayName
A24: Analysis Level | B24: AnalysisLevel | C24: Notes | D24: Comments | E24: Shape | F24: SiteShape | G24: Electrical | H24: ElectricalComments
A25: Purpose | B25: Purposes | C25: Confidential | D25: Privacy | E25: Topography | F25: SiteTopography | G25: Interior Walls | H25: InteriorWallComments
A26: Values | B26: RequestedValues | C26: Name | D26: Name | E26: Site Grade | F26: SiteGrade | G26: Doors and Windows | H26: DoorAndWindowComments
A27: Staff 1 Role | B27: Staff1Role | C27: Address | D27: FullAddress | E27: Corner | F27: SiteCorner | G27: Ceilings | H27: CeilingComments
A28: Staff 2 Role | B28: Staff2Role | C28: Address | D28: FullAddressMultiLine | E28: Density | F28: Density | G28: Plumbing | H28: PlumbingComments
A29: Staff 3 Role | B29: Staff3Role | C29: Contact | D29: FullContactInformation | E29: Permitted FAR | F29: PermittedFAR | G29: Floor Coverings | H29: FloorComments
A30: Confidential | B30: Privacy | C30: Created | D30: CreatedTime | E30: Permitted Building Height | F30: PermittedBuildingHeight | G30: Fire Safety | H30: SafetyFeaturesComments
A31: General | B31: Comments | C31: Updated | D31: ModifiedTime | E31: Proposed Land Use | F31: ProposedLandUse | G31: Interior Finish/Build-Out | H31: InteriorFinishComments
A32: Client | B32: ClientComments | C32: Display Name | D32: _DisplayName | E32: Site H&BU | F32: SiteHBU | G32: Site Improvements | H32: SiteImprovementComments
A33: Delivery | B33: DeliveryComments | C33: Office | D33: Office._DisplayName | E33: Off-Site Improvements | F33: OffSiteImprovements | G33: Deferred Maintenance | H33: DeferredMaintenanceComments
A34: Payment | B34: PaymentComments | C34: Relationship Owner | D34: Owner._DisplayName | E34: View | F34: SiteView | G34: Gross Building Area (GBA) | H34: GrossBuildingArea
A35: Amount Outstanding | B35: AmountOutstanding | C35: Files | D35: _DisplayName | E35: Utilities | F35: Utilities | G35: Net Rentable Area (NRA) | H35: NetRentableArea
A36: Days Sales Outstanding | B36: DaysToPaid | C36: CustomFields | D36: _DisplayName | E36: Easements | F36: Easements | G36: First Floor Footprint (SF) | H36: FootprintArea
A37: Aging | B37: DaysSinceInvoiced | E37: Entitlements | F37: Entitlements | G37: Finished Basement (SF) | H37: FinishedBasementArea
A38: Appraisers | B38: StaffAppraisers | E38: Environmental | F38: EnvironmentalIssues | G38: Unfinished Basement (SF) | H38: UnfinishedBasementArea
A39: Assistants | B39: StaffAssistants | E39: Frontage | F39: Frontage | G39: Warehouse Area (SF) | H39: WarehouseArea
A40: Procurers | B40: StaffProcurers | E40: Flood Zones | F40: SiteFloodZone | G40: Office Area (SF) | H40: OfficeArea
A41: Reviewers | B41: StaffReviewers | E41: Project Design | F41: ProjectDesign | G41: Office Buildout | H41: OfficeBuildoutRatio
...

Sheet TBD
A1: Rule ID | B1: Rule Set ID | C1: Rule Group | D1: Rule Role | E1: Logic Type | F1: Rule Type | G1: Valta Field Name | H1: Operator | I1: Dropdown Value | K1: Valta Field Name | L1: Result Value | M1: Text ID | N1: Priority
A2: R001 | B2: 100-Interest | C2: Interest Rule | D2: =+Types!F4 | E2: =+Types!H2 | F2: Set Value | G2: =+'Field Registry'!C15 | H2: = | I2: =+tblPropertyType[[#This Row],[ListPropertyType]] | K2: =+'Field Registry'!C22 | L2: =+'Dropdown Lists'!E2 | M2: None
A3: R002 | B3: 100-Interest | C3: Interest Rule | D3: =+D2 | E3: And | F3: Set Value | H3: = | I3: =+tblPropertyType[[#This Row],[ListPropertyType]] | L3: =+'Dropdown Lists'!E2 | M3: None
A4: R003 | B4: 100-Interest | C4: Interest Rule | D4: Condition + Output | E4: And | F4: Set Value | H4: = | I4: =+tblPropertyType[[#This Row],[ListPropertyType]] | L4: =+'Dropdown Lists'!E3 | M4: None
A5: R004 | B5: 100-Interest | C5: Interest Rule | D5: Condition + Output | E5: And | F5: Set Value | H5: = | I5: =+tblPropertyType[[#This Row],[ListPropertyType]] | L5: =+'Dropdown Lists'!E3 | M5: None
A6: R005 | B6: 100-Interest | C6: Interest Rule | D6: Condition + Output | E6: And | F6: Set Value | H6: = | I6: =+tblPropertyType[[#This Row],[ListPropertyType]] | L6: =+'Dropdown Lists'!E3 | M6: None
A7: R006 | B7: 100-Interest | C7: Interest Rule | D7: Condition + Output | E7: And | F7: Set Value | H7: = | I7: =+tblPropertyType[[#This Row],[ListPropertyType]] | L7: =+'Dropdown Lists'!E2 | M7: None
A8: R007 | B8: 100-Interest | C8: Interest Rule | D8: Condition + Output | E8: And | F8: Set Value | H8: = | I8: =+tblPropertyType[[#This Row],[ListPropertyType]] | L8: =+L2 | M8: None
A9: R008 | B9: 100-Interest | C9: Interest Rule | D9: Condition + Output | E9: And | F9: Set Value | H9: = | I9: =+tblPropertyType[[#This Row],[ListPropertyType]] | L9: =+L2 | M9: None
A10: R009 | B10: 100-Interest | C10: Interest Rule | D10: Condition + Output | E10: And | F10: Set Value | G10: =+'Field Registry'!C17 | H10: = | I10: Owner-Occupied | K10: InterestAppraised | L10: Fee Simple
H11: = | I11: Multi-Tenant | L11: Leased Fee Interest
H12: = | I12: Partial Owner Occupied | L12: Leasehold Estate
H13: = | I13: Single-Tenant | L13: Going Concern
H14: = | I14: Unkown
H15: = | I15: Vacant
A16: R010 | B16: 100-Interest | C16: Interest Rule | D16: Condition + Output | E16: And | F16: Set Value | G16: =+'Field Registry'!C16 | H16: = | I16: =+'Dropdown Lists'!C4 | K16: InterestAppraised | L16: Fee Simple & Lease Fee | M16: None
A17: R011 | B17: 200-Scenario | C17: Scenario Rule | D17: Condition + Output | E17: And | F17: Add Value | G17: =+'Field Registry'!C19 | H17: = | I17: =+'Dropdown Lists'!I2 | K17: =+'Field Registry'!C24 | L17: =+'Dropdown Lists'!M6 | M17: None
A18: R012 | B18: 200-Scenario | C18: Scenario Rule | D18: Condition + Output | E18: And | F18: Add Value | H18: = | I18: =+'Dropdown Lists'!I3 | L18: =+'Dropdown Lists'!M6 | M18: None
A19: R013 | B19: 200-Scenario | C19: Scenario Rule | D19: Condition + Output | E19: And | F19: Add Value | H19: = | I19: =+'Dropdown Lists'!I4 | L19: As Is | M19: None
A20: R014 | B20: 200-Scenario | C20: Scenario Rule | D20: Condition + Output | E20: And | F20: Add Value | H20: = | I20: =+I19 | L20: As If Complete & Stabilized | M20: None
A21: R015 | B21: 200-Scenario | C21: Scenario Rule | D21: Condition + Output | E21: And | F21: Add Value | H21: = | I21: =+'Dropdown Lists'!I5 | L21: As Is | M21: None
A22: R016 | B22: 200-Scenario | C22: Scenario Rule | D22: Condition + Output | E22: And | F22: Add Value | H22: = | I22: =+'Dropdown Lists'!I5 | L22: =+L20 | M22: None
A23: R017 | B23: 200-Scenario | C23: Scenario Rule | D23: Condition + Output | E23: And | F23: Add Value | H23: = | I23: =+'Dropdown Lists'!I6 | L23: As Is Vacant Land | M23: None
A24: R018 | B24: 200-Scenario | C24: Scenario Rule | D24: Condition + Output | E24: And | F24: Add Value | H24: = | I24: =+I23 | L24: As If Complete & Stabilized | M24: None
A25: R019 | B25: 200-Scenario | C25: Scenario Rule | D25: Condition + Output | E25: And | F25: Add Value | H25: = | I25: =+'Dropdown Lists'!I7 | L25: As If Vacant | M25: None
A26: R020 | B26: 200-Scenario | C26: Scenario Rule | D26: Condition + Output | E26: And | F26: Add Value | H26: = | I26: =+I25 | L26: As If Complete & Stabilized | M26: None
A27: R021 | B27: 200-Scenario | C27: Scenario Rule | D27: Condition + Output | E27: And | F27: Add Value | H27: = | I27: =+'Dropdown Lists'!I8 | L27: As If Vacant | M27: None
A28: R022 | B28: 200-Scenario | C28: Scenario Rule | D28: Condition + Output | E28: And | F28: Add Value | H28: = | I28: =+I27 | L28: As If Complete & Stabilized | M28: None
A29: R023 | B29: 200-Scenario | C29: Scenario Rule | D29: Condition + Output | E29: And | F29: Set Value | G29: AuthorizedUse | H29: = | I29: Insurance | L29: Insurable Replacement Cost | M29: None
A30: R024 | B30: 300-Approach | C30: Approach Rule | D30: Condition + Output | E30: And | F30: Add Value | G30: =+'Field Registry'!C24 | H30: = | I30: =+'Dropdown Lists'!M6 | K30: =+'Field Registry'!C25 | L30: Direct Comparison | M30: None
A31: R025 | B31: 300-Approach | C31: Approach Rule | D31: Condition + Output | E31: And | F31: Add Value | G31: =+G30 | H31: = | I31: As Stabilized | K31: =+K30 | L31: Income Approach | M31: None
A32: R026 | B32: 300-Approach | C32: Approach Rule | D32: Condition + Output | E32: And | F32: Add Value | G32: =+G31 | H32: = | I32: As Is Vacant Land | K32: =+K31 | L32: =+'Dropdown Lists'!N2 | M32: None
A33: R027 | B33: 300-Approach | C33: Approach Rule | D33: Condition + Output | E33: And | F33: Add Value | G33: =+G32 | H33: = | I33: =+'Dropdown Lists'!M3 | K33: =+K32 | L33: =+L32 | M33: None
A34: R028 | B34: 300-Approach | C34: Approach Rule | D34: Condition + Output | E34: And | F34: Add Value | G34: =+G33 | H34: = | I34: =+'Dropdown Lists'!M4 | K34: =+K33 | L34: =+'Dropdown Lists'!N3 | M34: None
C39: =+Types!L7 | F39: Insert EA/HC Text | G39: ValueScenarios | I39: =+'Dropdown Lists'!M3 | K39: EA Text | L39: N/A | M39: The As If Vacant market land value is developed under the hypothetical condition that the existing improvements on the subject site do not exist, and that the property is vacant as of the effective date. This condition is contrary to the known physical state of the property and is made for the purpose of estimating the underlying land value.
C40: =+C39 | F40: Insert EA/HC Text | G40: =+G39 | I40: =+'Dropdown Lists'!M6 | K40: =+K39 | L40: =+L39
